2016-08-31 03:01:28,812 ERROR: Exception on /api/goals [GET] [in /Users/ladia/Documents/bucketlist/venv/lib/python2.7/site-packages/flask/app.py:1423]
Traceback (most recent call last):
  File "/Users/ladia/Documents/bucketlist/venv/lib/python2.7/site-packages/flask/app.py", line 1817, in wsgi_app
    response = self.full_dispatch_request()
  File "/Users/ladia/Documents/bucketlist/venv/lib/python2.7/site-packages/flask/app.py", line 1477, in full_dispatch_request
    rv = self.handle_user_exception(e)
  File "/Users/ladia/Documents/bucketlist/venv/lib/python2.7/site-packages/flask/app.py", line 1381, in handle_user_exception
    reraise(exc_type, exc_value, tb)
  File "/Users/ladia/Documents/bucketlist/venv/lib/python2.7/site-packages/flask/app.py", line 1475, in full_dispatch_request
    rv = self.dispatch_request()
  File "/Users/ladia/Documents/bucketlist/venv/lib/python2.7/site-packages/flask/app.py", line 1461, in dispatch_request
    return self.view_functions[rule.endpoint](**req.view_args)
  File "/Users/ladia/Documents/bucketlist/venv/lib/python2.7/site-packages/flask_httpauth.py", line 54, in decorated
    return f(*args, **kwargs)
  File "/Users/ladia/Documents/bucketlist/bucketlist.py", line 163, in get_all_goals
    return jsonify([i.serialize for i in goals]), 200
AttributeError: 'Goal' object has no attribute 'serialize'
2016-09-04 14:02:27,916 ERROR: Exception on /api/goals [GET] [in /Users/ladia/Documents/bucketlist/venv/lib/python2.7/site-packages/flask/app.py:1423]
Traceback (most recent call last):
  File "/Users/ladia/Documents/bucketlist/venv/lib/python2.7/site-packages/flask/app.py", line 1817, in wsgi_app
    response = self.full_dispatch_request()
  File "/Users/ladia/Documents/bucketlist/venv/lib/python2.7/site-packages/flask/app.py", line 1477, in full_dispatch_request
    rv = self.handle_user_exception(e)
  File "/Users/ladia/Documents/bucketlist/venv/lib/python2.7/site-packages/flask/app.py", line 1381, in handle_user_exception
    reraise(exc_type, exc_value, tb)
  File "/Users/ladia/Documents/bucketlist/venv/lib/python2.7/site-packages/flask/app.py", line 1475, in full_dispatch_request
    rv = self.dispatch_request()
  File "/Users/ladia/Documents/bucketlist/venv/lib/python2.7/site-packages/flask/app.py", line 1461, in dispatch_request
    return self.view_functions[rule.endpoint](**req.view_args)
  File "/Users/ladia/Documents/bucketlist/venv/lib/python2.7/site-packages/flask_httpauth.py", line 54, in decorated
    return f(*args, **kwargs)
  File "/Users/ladia/Documents/bucketlist/bucketlist.py", line 163, in get_all_goals
    return jsonify([i.serialize for i in goals]), 200
  File "/Users/ladia/Documents/bucketlist/models/models.py", line 53, in serialize
    'first_name': self.user.first_name,
AttributeError: 'NoneType' object has no attribute 'first_name'
2016-09-04 14:26:44,482 ERROR: Exception on /api/goals [GET] [in /Users/ladia/Documents/bucketlist/venv/lib/python2.7/site-packages/flask/app.py:1423]
Traceback (most recent call last):
  File "/Users/ladia/Documents/bucketlist/venv/lib/python2.7/site-packages/flask/app.py", line 1817, in wsgi_app
    response = self.full_dispatch_request()
  File "/Users/ladia/Documents/bucketlist/venv/lib/python2.7/site-packages/flask/app.py", line 1477, in full_dispatch_request
    rv = self.handle_user_exception(e)
  File "/Users/ladia/Documents/bucketlist/venv/lib/python2.7/site-packages/flask/app.py", line 1381, in handle_user_exception
    reraise(exc_type, exc_value, tb)
  File "/Users/ladia/Documents/bucketlist/venv/lib/python2.7/site-packages/flask/app.py", line 1475, in full_dispatch_request
    rv = self.dispatch_request()
  File "/Users/ladia/Documents/bucketlist/venv/lib/python2.7/site-packages/flask/app.py", line 1461, in dispatch_request
    return self.view_functions[rule.endpoint](**req.view_args)
  File "/Users/ladia/Documents/bucketlist/venv/lib/python2.7/site-packages/flask_httpauth.py", line 54, in decorated
    return f(*args, **kwargs)
  File "/Users/ladia/Documents/bucketlist/bucketlist.py", line 163, in get_all_goals
    return jsonify([i.serialize for i in goals]), 200
  File "/Users/ladia/Documents/bucketlist/models/models.py", line 53, in serialize
    'first_name': self.user.first_name,
AttributeError: 'NoneType' object has no attribute 'first_name'
2016-09-04 14:27:12,301 ERROR: Exception on /api/goals [GET] [in /Users/ladia/Documents/bucketlist/venv/lib/python2.7/site-packages/flask/app.py:1423]
Traceback (most recent call last):
  File "/Users/ladia/Documents/bucketlist/venv/lib/python2.7/site-packages/flask/app.py", line 1817, in wsgi_app
    response = self.full_dispatch_request()
  File "/Users/ladia/Documents/bucketlist/venv/lib/python2.7/site-packages/flask/app.py", line 1477, in full_dispatch_request
    rv = self.handle_user_exception(e)
  File "/Users/ladia/Documents/bucketlist/venv/lib/python2.7/site-packages/flask/app.py", line 1381, in handle_user_exception
    reraise(exc_type, exc_value, tb)
  File "/Users/ladia/Documents/bucketlist/venv/lib/python2.7/site-packages/flask/app.py", line 1475, in full_dispatch_request
    rv = self.dispatch_request()
  File "/Users/ladia/Documents/bucketlist/venv/lib/python2.7/site-packages/flask/app.py", line 1461, in dispatch_request
    return self.view_functions[rule.endpoint](**req.view_args)
  File "/Users/ladia/Documents/bucketlist/venv/lib/python2.7/site-packages/flask_httpauth.py", line 54, in decorated
    return f(*args, **kwargs)
  File "/Users/ladia/Documents/bucketlist/bucketlist.py", line 163, in get_all_goals
    return jsonify([i.serialize for i in goals]), 200
  File "/Users/ladia/Documents/bucketlist/venv/lib/python2.7/site-packages/flask/json.py", line 237, in jsonify
    return current_app.response_class(dumps(dict(*args, **kwargs),
ValueError: dictionary update sequence element #0 has length 11; 2 is required
2016-09-04 14:29:46,500 ERROR: Exception on /api/goals [GET] [in /Users/ladia/Documents/bucketlist/venv/lib/python2.7/site-packages/flask/app.py:1423]
Traceback (most recent call last):
  File "/Users/ladia/Documents/bucketlist/venv/lib/python2.7/site-packages/flask/app.py", line 1817, in wsgi_app
    response = self.full_dispatch_request()
  File "/Users/ladia/Documents/bucketlist/venv/lib/python2.7/site-packages/flask/app.py", line 1477, in full_dispatch_request
    rv = self.handle_user_exception(e)
  File "/Users/ladia/Documents/bucketlist/venv/lib/python2.7/site-packages/flask/app.py", line 1381, in handle_user_exception
    reraise(exc_type, exc_value, tb)
  File "/Users/ladia/Documents/bucketlist/venv/lib/python2.7/site-packages/flask/app.py", line 1475, in full_dispatch_request
    rv = self.dispatch_request()
  File "/Users/ladia/Documents/bucketlist/venv/lib/python2.7/site-packages/flask/app.py", line 1461, in dispatch_request
    return self.view_functions[rule.endpoint](**req.view_args)
  File "/Users/ladia/Documents/bucketlist/venv/lib/python2.7/site-packages/flask_httpauth.py", line 54, in decorated
    return f(*args, **kwargs)
  File "/Users/ladia/Documents/bucketlist/bucketlist.py", line 163, in get_all_goals
    return jsonify([i.serialize for i in goals]), 200
  File "/Users/ladia/Documents/bucketlist/venv/lib/python2.7/site-packages/flask/json.py", line 237, in jsonify
    return current_app.response_class(dumps(dict(*args, **kwargs),
ValueError: dictionary update sequence element #0 has length 11; 2 is required
2016-09-04 18:37:48,548 ERROR: Exception on /api/goals/11/like [POST] [in /Users/ladia/Documents/bucketlist/venv/lib/python2.7/site-packages/flask/app.py:1423]
Traceback (most recent call last):
  File "/Users/ladia/Documents/bucketlist/venv/lib/python2.7/site-packages/flask/app.py", line 1817, in wsgi_app
    response = self.full_dispatch_request()
  File "/Users/ladia/Documents/bucketlist/venv/lib/python2.7/site-packages/flask/app.py", line 1477, in full_dispatch_request
    rv = self.handle_user_exception(e)
  File "/Users/ladia/Documents/bucketlist/venv/lib/python2.7/site-packages/flask/app.py", line 1381, in handle_user_exception
    reraise(exc_type, exc_value, tb)
  File "/Users/ladia/Documents/bucketlist/venv/lib/python2.7/site-packages/flask/app.py", line 1475, in full_dispatch_request
    rv = self.dispatch_request()
  File "/Users/ladia/Documents/bucketlist/venv/lib/python2.7/site-packages/flask/app.py", line 1461, in dispatch_request
    return self.view_functions[rule.endpoint](**req.view_args)
  File "/Users/ladia/Documents/bucketlist/bucketlist.py", line 168, in like_goal
    user = g.user
  File "/Users/ladia/Documents/bucketlist/venv/lib/python2.7/site-packages/werkzeug/local.py", line 343, in __getattr__
    return getattr(self._get_current_object(), name)
AttributeError: '_AppCtxGlobals' object has no attribute 'user'
2016-09-04 18:40:05,904 ERROR: Exception on /api/goals/11/like [POST] [in /Users/ladia/Documents/bucketlist/venv/lib/python2.7/site-packages/flask/app.py:1423]
Traceback (most recent call last):
  File "/Users/ladia/Documents/bucketlist/venv/lib/python2.7/site-packages/flask/app.py", line 1817, in wsgi_app
    response = self.full_dispatch_request()
  File "/Users/ladia/Documents/bucketlist/venv/lib/python2.7/site-packages/flask/app.py", line 1478, in full_dispatch_request
    response = self.make_response(rv)
  File "/Users/ladia/Documents/bucketlist/venv/lib/python2.7/site-packages/flask/app.py", line 1566, in make_response
    raise ValueError('View function did not return a response')
ValueError: View function did not return a response
